{
  "stats": {
    "submitted": 10,
    "finished": 10,
    "running": 0
  },
  "data": [
    [
      1,
      null,
      209652396,
      null,
      0.6451931491446117,
      0.10551595687866211,
      1,
      1694796375.2643242,
      1694796375.3709028,
      {}
    ],
    [
      1,
      null,
      398764591,
      null,
      0.6451931491446117,
      0.10585355758666992,
      1,
      1694796375.3731418,
      1694796375.4800909,
      {}
    ],
    [
      2,
      null,
      209652396,
      null,
      Infinity,
      0.0,
      2,
      1694796375.4825141,
      1694796375.4894638,
      {
        "traceback": "Traceback (most recent call last):\n  File \"/mnt/belinda_local/daniel/home/anaconda3/envs/GenerativeAI/lib/python3.11/site-packages/smac/runner/target_function_runner.py\", line 184, in run\n    rval = self(config_copy, target_function, kwargs)\n           ^^^^^^^^^^^^^^^^^^^^^^^^^^^^^^^^^^^^^^^^^^\n  File \"/mnt/belinda_local/daniel/home/anaconda3/envs/GenerativeAI/lib/python3.11/site-packages/smac/runner/target_function_runner.py\", line 257, in __call__\n    return algorithm(config, **algorithm_kwargs)\n           ^^^^^^^^^^^^^^^^^^^^^^^^^^^^^^^^^^^^^\n  File \"/mnt/belinda_local/daniel/home/AutoMF/AutoMFBO2.py\", line 737, in train\n    X, X_r = Kernel_PCA(X_scaled, **config_dict)\n             ^^^^^^^^^^^^^^^^^^^^^^^^^^^^^^^^^^^\n  File \"/mnt/belinda_local/daniel/home/AutoMF/AutoMFBO2.py\", line 58, in Kernel_PCA\n    W = model.fit_transform(X)\n        ^^^^^^^^^^^^^^^^^^^^^^\n  File \"/mnt/belinda_local/daniel/home/anaconda3/envs/GenerativeAI/lib/python3.11/site-packages/sklearn/utils/_set_output.py\", line 140, in wrapped\n    data_to_wrap = f(self, X, *args, **kwargs)\n                   ^^^^^^^^^^^^^^^^^^^^^^^^^^^\n  File \"/mnt/belinda_local/daniel/home/anaconda3/envs/GenerativeAI/lib/python3.11/site-packages/sklearn/decomposition/_kernel_pca.py\", line 456, in fit_transform\n    self.fit(X, **params)\n  File \"/mnt/belinda_local/daniel/home/anaconda3/envs/GenerativeAI/lib/python3.11/site-packages/sklearn/decomposition/_kernel_pca.py\", line 424, in fit\n    self._fit_transform(K)\n  File \"/mnt/belinda_local/daniel/home/anaconda3/envs/GenerativeAI/lib/python3.11/site-packages/sklearn/decomposition/_kernel_pca.py\", line 348, in _fit_transform\n    self.eigenvalues_ = _check_psd_eigenvalues(\n                        ^^^^^^^^^^^^^^^^^^^^^^^\n  File \"/mnt/belinda_local/daniel/home/anaconda3/envs/GenerativeAI/lib/python3.11/site-packages/sklearn/utils/validation.py\", line 1681, in _check_psd_eigenvalues\n    raise ValueError(\nValueError: There are significant negative eigenvalues (11.2454 of the maximum positive). Either the matrix is not PSD, or there was an issue while computing the eigendecomposition of the matrix.\n",
        "error": "ValueError('There are significant negative eigenvalues (11.2454 of the maximum positive). Either the matrix is not PSD, or there was an issue while computing the eigendecomposition of the matrix.')"
      }
    ],
    [
      2,
      null,
      398764591,
      null,
      Infinity,
      0.0,
      2,
      1694796375.4920938,
      1694796375.4973621,
      {
        "traceback": "Traceback (most recent call last):\n  File \"/mnt/belinda_local/daniel/home/anaconda3/envs/GenerativeAI/lib/python3.11/site-packages/smac/runner/target_function_runner.py\", line 184, in run\n    rval = self(config_copy, target_function, kwargs)\n           ^^^^^^^^^^^^^^^^^^^^^^^^^^^^^^^^^^^^^^^^^^\n  File \"/mnt/belinda_local/daniel/home/anaconda3/envs/GenerativeAI/lib/python3.11/site-packages/smac/runner/target_function_runner.py\", line 257, in __call__\n    return algorithm(config, **algorithm_kwargs)\n           ^^^^^^^^^^^^^^^^^^^^^^^^^^^^^^^^^^^^^\n  File \"/mnt/belinda_local/daniel/home/AutoMF/AutoMFBO2.py\", line 737, in train\n    X, X_r = Kernel_PCA(X_scaled, **config_dict)\n             ^^^^^^^^^^^^^^^^^^^^^^^^^^^^^^^^^^^\n  File \"/mnt/belinda_local/daniel/home/AutoMF/AutoMFBO2.py\", line 58, in Kernel_PCA\n    W = model.fit_transform(X)\n        ^^^^^^^^^^^^^^^^^^^^^^\n  File \"/mnt/belinda_local/daniel/home/anaconda3/envs/GenerativeAI/lib/python3.11/site-packages/sklearn/utils/_set_output.py\", line 140, in wrapped\n    data_to_wrap = f(self, X, *args, **kwargs)\n                   ^^^^^^^^^^^^^^^^^^^^^^^^^^^\n  File \"/mnt/belinda_local/daniel/home/anaconda3/envs/GenerativeAI/lib/python3.11/site-packages/sklearn/decomposition/_kernel_pca.py\", line 456, in fit_transform\n    self.fit(X, **params)\n  File \"/mnt/belinda_local/daniel/home/anaconda3/envs/GenerativeAI/lib/python3.11/site-packages/sklearn/decomposition/_kernel_pca.py\", line 424, in fit\n    self._fit_transform(K)\n  File \"/mnt/belinda_local/daniel/home/anaconda3/envs/GenerativeAI/lib/python3.11/site-packages/sklearn/decomposition/_kernel_pca.py\", line 348, in _fit_transform\n    self.eigenvalues_ = _check_psd_eigenvalues(\n                        ^^^^^^^^^^^^^^^^^^^^^^^\n  File \"/mnt/belinda_local/daniel/home/anaconda3/envs/GenerativeAI/lib/python3.11/site-packages/sklearn/utils/validation.py\", line 1681, in _check_psd_eigenvalues\n    raise ValueError(\nValueError: There are significant negative eigenvalues (11.2454 of the maximum positive). Either the matrix is not PSD, or there was an issue while computing the eigendecomposition of the matrix.\n",
        "error": "ValueError('There are significant negative eigenvalues (11.2454 of the maximum positive). Either the matrix is not PSD, or there was an issue while computing the eigendecomposition of the matrix.')"
      }
    ],
    [
      1,
      null,
      924231285,
      null,
      0.6451931491446117,
      0.1032567024230957,
      1,
      1694796375.500464,
      1694796375.604876,
      {}
    ],
    [
      3,
      null,
      209652396,
      null,
      Infinity,
      0.0,
      2,
      1694796375.7674422,
      1694796375.7732012,
      {
        "traceback": "Traceback (most recent call last):\n  File \"/mnt/belinda_local/daniel/home/anaconda3/envs/GenerativeAI/lib/python3.11/site-packages/smac/runner/target_function_runner.py\", line 184, in run\n    rval = self(config_copy, target_function, kwargs)\n           ^^^^^^^^^^^^^^^^^^^^^^^^^^^^^^^^^^^^^^^^^^\n  File \"/mnt/belinda_local/daniel/home/anaconda3/envs/GenerativeAI/lib/python3.11/site-packages/smac/runner/target_function_runner.py\", line 257, in __call__\n    return algorithm(config, **algorithm_kwargs)\n           ^^^^^^^^^^^^^^^^^^^^^^^^^^^^^^^^^^^^^\n  File \"/mnt/belinda_local/daniel/home/AutoMF/AutoMFBO2.py\", line 737, in train\n    X, X_r = Kernel_PCA(X_scaled, **config_dict)\n             ^^^^^^^^^^^^^^^^^^^^^^^^^^^^^^^^^^^\n  File \"/mnt/belinda_local/daniel/home/AutoMF/AutoMFBO2.py\", line 58, in Kernel_PCA\n    W = model.fit_transform(X)\n        ^^^^^^^^^^^^^^^^^^^^^^\n  File \"/mnt/belinda_local/daniel/home/anaconda3/envs/GenerativeAI/lib/python3.11/site-packages/sklearn/utils/_set_output.py\", line 140, in wrapped\n    data_to_wrap = f(self, X, *args, **kwargs)\n                   ^^^^^^^^^^^^^^^^^^^^^^^^^^^\n  File \"/mnt/belinda_local/daniel/home/anaconda3/envs/GenerativeAI/lib/python3.11/site-packages/sklearn/decomposition/_kernel_pca.py\", line 456, in fit_transform\n    self.fit(X, **params)\n  File \"/mnt/belinda_local/daniel/home/anaconda3/envs/GenerativeAI/lib/python3.11/site-packages/sklearn/decomposition/_kernel_pca.py\", line 424, in fit\n    self._fit_transform(K)\n  File \"/mnt/belinda_local/daniel/home/anaconda3/envs/GenerativeAI/lib/python3.11/site-packages/sklearn/decomposition/_kernel_pca.py\", line 348, in _fit_transform\n    self.eigenvalues_ = _check_psd_eigenvalues(\n                        ^^^^^^^^^^^^^^^^^^^^^^^\n  File \"/mnt/belinda_local/daniel/home/anaconda3/envs/GenerativeAI/lib/python3.11/site-packages/sklearn/utils/validation.py\", line 1681, in _check_psd_eigenvalues\n    raise ValueError(\nValueError: There are significant negative eigenvalues (11.2454 of the maximum positive). Either the matrix is not PSD, or there was an issue while computing the eigendecomposition of the matrix.\n",
        "error": "ValueError('There are significant negative eigenvalues (11.2454 of the maximum positive). Either the matrix is not PSD, or there was an issue while computing the eigendecomposition of the matrix.')"
      }
    ],
    [
      3,
      null,
      398764591,
      null,
      Infinity,
      0.0,
      2,
      1694796375.7759345,
      1694796375.7815099,
      {
        "traceback": "Traceback (most recent call last):\n  File \"/mnt/belinda_local/daniel/home/anaconda3/envs/GenerativeAI/lib/python3.11/site-packages/smac/runner/target_function_runner.py\", line 184, in run\n    rval = self(config_copy, target_function, kwargs)\n           ^^^^^^^^^^^^^^^^^^^^^^^^^^^^^^^^^^^^^^^^^^\n  File \"/mnt/belinda_local/daniel/home/anaconda3/envs/GenerativeAI/lib/python3.11/site-packages/smac/runner/target_function_runner.py\", line 257, in __call__\n    return algorithm(config, **algorithm_kwargs)\n           ^^^^^^^^^^^^^^^^^^^^^^^^^^^^^^^^^^^^^\n  File \"/mnt/belinda_local/daniel/home/AutoMF/AutoMFBO2.py\", line 737, in train\n    X, X_r = Kernel_PCA(X_scaled, **config_dict)\n             ^^^^^^^^^^^^^^^^^^^^^^^^^^^^^^^^^^^\n  File \"/mnt/belinda_local/daniel/home/AutoMF/AutoMFBO2.py\", line 58, in Kernel_PCA\n    W = model.fit_transform(X)\n        ^^^^^^^^^^^^^^^^^^^^^^\n  File \"/mnt/belinda_local/daniel/home/anaconda3/envs/GenerativeAI/lib/python3.11/site-packages/sklearn/utils/_set_output.py\", line 140, in wrapped\n    data_to_wrap = f(self, X, *args, **kwargs)\n                   ^^^^^^^^^^^^^^^^^^^^^^^^^^^\n  File \"/mnt/belinda_local/daniel/home/anaconda3/envs/GenerativeAI/lib/python3.11/site-packages/sklearn/decomposition/_kernel_pca.py\", line 456, in fit_transform\n    self.fit(X, **params)\n  File \"/mnt/belinda_local/daniel/home/anaconda3/envs/GenerativeAI/lib/python3.11/site-packages/sklearn/decomposition/_kernel_pca.py\", line 424, in fit\n    self._fit_transform(K)\n  File \"/mnt/belinda_local/daniel/home/anaconda3/envs/GenerativeAI/lib/python3.11/site-packages/sklearn/decomposition/_kernel_pca.py\", line 348, in _fit_transform\n    self.eigenvalues_ = _check_psd_eigenvalues(\n                        ^^^^^^^^^^^^^^^^^^^^^^^\n  File \"/mnt/belinda_local/daniel/home/anaconda3/envs/GenerativeAI/lib/python3.11/site-packages/sklearn/utils/validation.py\", line 1681, in _check_psd_eigenvalues\n    raise ValueError(\nValueError: There are significant negative eigenvalues (11.2454 of the maximum positive). Either the matrix is not PSD, or there was an issue while computing the eigendecomposition of the matrix.\n",
        "error": "ValueError('There are significant negative eigenvalues (11.2454 of the maximum positive). Either the matrix is not PSD, or there was an issue while computing the eigendecomposition of the matrix.')"
      }
    ],
    [
      3,
      null,
      924231285,
      null,
      Infinity,
      0.0,
      2,
      1694796375.7841113,
      1694796375.7895713,
      {
        "traceback": "Traceback (most recent call last):\n  File \"/mnt/belinda_local/daniel/home/anaconda3/envs/GenerativeAI/lib/python3.11/site-packages/smac/runner/target_function_runner.py\", line 184, in run\n    rval = self(config_copy, target_function, kwargs)\n           ^^^^^^^^^^^^^^^^^^^^^^^^^^^^^^^^^^^^^^^^^^\n  File \"/mnt/belinda_local/daniel/home/anaconda3/envs/GenerativeAI/lib/python3.11/site-packages/smac/runner/target_function_runner.py\", line 257, in __call__\n    return algorithm(config, **algorithm_kwargs)\n           ^^^^^^^^^^^^^^^^^^^^^^^^^^^^^^^^^^^^^\n  File \"/mnt/belinda_local/daniel/home/AutoMF/AutoMFBO2.py\", line 737, in train\n    X, X_r = Kernel_PCA(X_scaled, **config_dict)\n             ^^^^^^^^^^^^^^^^^^^^^^^^^^^^^^^^^^^\n  File \"/mnt/belinda_local/daniel/home/AutoMF/AutoMFBO2.py\", line 58, in Kernel_PCA\n    W = model.fit_transform(X)\n        ^^^^^^^^^^^^^^^^^^^^^^\n  File \"/mnt/belinda_local/daniel/home/anaconda3/envs/GenerativeAI/lib/python3.11/site-packages/sklearn/utils/_set_output.py\", line 140, in wrapped\n    data_to_wrap = f(self, X, *args, **kwargs)\n                   ^^^^^^^^^^^^^^^^^^^^^^^^^^^\n  File \"/mnt/belinda_local/daniel/home/anaconda3/envs/GenerativeAI/lib/python3.11/site-packages/sklearn/decomposition/_kernel_pca.py\", line 456, in fit_transform\n    self.fit(X, **params)\n  File \"/mnt/belinda_local/daniel/home/anaconda3/envs/GenerativeAI/lib/python3.11/site-packages/sklearn/decomposition/_kernel_pca.py\", line 424, in fit\n    self._fit_transform(K)\n  File \"/mnt/belinda_local/daniel/home/anaconda3/envs/GenerativeAI/lib/python3.11/site-packages/sklearn/decomposition/_kernel_pca.py\", line 348, in _fit_transform\n    self.eigenvalues_ = _check_psd_eigenvalues(\n                        ^^^^^^^^^^^^^^^^^^^^^^^\n  File \"/mnt/belinda_local/daniel/home/anaconda3/envs/GenerativeAI/lib/python3.11/site-packages/sklearn/utils/validation.py\", line 1681, in _check_psd_eigenvalues\n    raise ValueError(\nValueError: There are significant negative eigenvalues (11.2454 of the maximum positive). Either the matrix is not PSD, or there was an issue while computing the eigendecomposition of the matrix.\n",
        "error": "ValueError('There are significant negative eigenvalues (11.2454 of the maximum positive). Either the matrix is not PSD, or there was an issue while computing the eigendecomposition of the matrix.')"
      }
    ],
    [
      4,
      null,
      209652396,
      null,
      Infinity,
      0.0,
      2,
      1694796375.792925,
      1694796375.798406,
      {
        "traceback": "Traceback (most recent call last):\n  File \"/mnt/belinda_local/daniel/home/anaconda3/envs/GenerativeAI/lib/python3.11/site-packages/smac/runner/target_function_runner.py\", line 184, in run\n    rval = self(config_copy, target_function, kwargs)\n           ^^^^^^^^^^^^^^^^^^^^^^^^^^^^^^^^^^^^^^^^^^\n  File \"/mnt/belinda_local/daniel/home/anaconda3/envs/GenerativeAI/lib/python3.11/site-packages/smac/runner/target_function_runner.py\", line 257, in __call__\n    return algorithm(config, **algorithm_kwargs)\n           ^^^^^^^^^^^^^^^^^^^^^^^^^^^^^^^^^^^^^\n  File \"/mnt/belinda_local/daniel/home/AutoMF/AutoMFBO2.py\", line 737, in train\n    X, X_r = Kernel_PCA(X_scaled, **config_dict)\n             ^^^^^^^^^^^^^^^^^^^^^^^^^^^^^^^^^^^\n  File \"/mnt/belinda_local/daniel/home/AutoMF/AutoMFBO2.py\", line 58, in Kernel_PCA\n    W = model.fit_transform(X)\n        ^^^^^^^^^^^^^^^^^^^^^^\n  File \"/mnt/belinda_local/daniel/home/anaconda3/envs/GenerativeAI/lib/python3.11/site-packages/sklearn/utils/_set_output.py\", line 140, in wrapped\n    data_to_wrap = f(self, X, *args, **kwargs)\n                   ^^^^^^^^^^^^^^^^^^^^^^^^^^^\n  File \"/mnt/belinda_local/daniel/home/anaconda3/envs/GenerativeAI/lib/python3.11/site-packages/sklearn/decomposition/_kernel_pca.py\", line 456, in fit_transform\n    self.fit(X, **params)\n  File \"/mnt/belinda_local/daniel/home/anaconda3/envs/GenerativeAI/lib/python3.11/site-packages/sklearn/decomposition/_kernel_pca.py\", line 424, in fit\n    self._fit_transform(K)\n  File \"/mnt/belinda_local/daniel/home/anaconda3/envs/GenerativeAI/lib/python3.11/site-packages/sklearn/decomposition/_kernel_pca.py\", line 348, in _fit_transform\n    self.eigenvalues_ = _check_psd_eigenvalues(\n                        ^^^^^^^^^^^^^^^^^^^^^^^\n  File \"/mnt/belinda_local/daniel/home/anaconda3/envs/GenerativeAI/lib/python3.11/site-packages/sklearn/utils/validation.py\", line 1681, in _check_psd_eigenvalues\n    raise ValueError(\nValueError: There are significant negative eigenvalues (11.2454 of the maximum positive). Either the matrix is not PSD, or there was an issue while computing the eigendecomposition of the matrix.\n",
        "error": "ValueError('There are significant negative eigenvalues (11.2454 of the maximum positive). Either the matrix is not PSD, or there was an issue while computing the eigendecomposition of the matrix.')"
      }
    ],
    [
      4,
      null,
      398764591,
      null,
      Infinity,
      0.0,
      2,
      1694796375.8011935,
      1694796375.8063927,
      {
        "traceback": "Traceback (most recent call last):\n  File \"/mnt/belinda_local/daniel/home/anaconda3/envs/GenerativeAI/lib/python3.11/site-packages/smac/runner/target_function_runner.py\", line 184, in run\n    rval = self(config_copy, target_function, kwargs)\n           ^^^^^^^^^^^^^^^^^^^^^^^^^^^^^^^^^^^^^^^^^^\n  File \"/mnt/belinda_local/daniel/home/anaconda3/envs/GenerativeAI/lib/python3.11/site-packages/smac/runner/target_function_runner.py\", line 257, in __call__\n    return algorithm(config, **algorithm_kwargs)\n           ^^^^^^^^^^^^^^^^^^^^^^^^^^^^^^^^^^^^^\n  File \"/mnt/belinda_local/daniel/home/AutoMF/AutoMFBO2.py\", line 737, in train\n    X, X_r = Kernel_PCA(X_scaled, **config_dict)\n             ^^^^^^^^^^^^^^^^^^^^^^^^^^^^^^^^^^^\n  File \"/mnt/belinda_local/daniel/home/AutoMF/AutoMFBO2.py\", line 58, in Kernel_PCA\n    W = model.fit_transform(X)\n        ^^^^^^^^^^^^^^^^^^^^^^\n  File \"/mnt/belinda_local/daniel/home/anaconda3/envs/GenerativeAI/lib/python3.11/site-packages/sklearn/utils/_set_output.py\", line 140, in wrapped\n    data_to_wrap = f(self, X, *args, **kwargs)\n                   ^^^^^^^^^^^^^^^^^^^^^^^^^^^\n  File \"/mnt/belinda_local/daniel/home/anaconda3/envs/GenerativeAI/lib/python3.11/site-packages/sklearn/decomposition/_kernel_pca.py\", line 456, in fit_transform\n    self.fit(X, **params)\n  File \"/mnt/belinda_local/daniel/home/anaconda3/envs/GenerativeAI/lib/python3.11/site-packages/sklearn/decomposition/_kernel_pca.py\", line 424, in fit\n    self._fit_transform(K)\n  File \"/mnt/belinda_local/daniel/home/anaconda3/envs/GenerativeAI/lib/python3.11/site-packages/sklearn/decomposition/_kernel_pca.py\", line 348, in _fit_transform\n    self.eigenvalues_ = _check_psd_eigenvalues(\n                        ^^^^^^^^^^^^^^^^^^^^^^^\n  File \"/mnt/belinda_local/daniel/home/anaconda3/envs/GenerativeAI/lib/python3.11/site-packages/sklearn/utils/validation.py\", line 1681, in _check_psd_eigenvalues\n    raise ValueError(\nValueError: There are significant negative eigenvalues (11.2454 of the maximum positive). Either the matrix is not PSD, or there was an issue while computing the eigendecomposition of the matrix.\n",
        "error": "ValueError('There are significant negative eigenvalues (11.2454 of the maximum positive). Either the matrix is not PSD, or there was an issue while computing the eigendecomposition of the matrix.')"
      }
    ]
  ],
  "configs": {
    "1": {
      "alpha": 0.34019066896289585,
      "degree": 4,
      "eigen_solver": "auto",
      "kernel": "poly",
      "n_components": 4
    },
    "2": {
      "alpha": 0.9592367018572986,
      "degree": 3,
      "eigen_solver": "randomized",
      "kernel": "sigmoid",
      "n_components": 2
    },
    "3": {
      "alpha": 0.9025957007038717,
      "degree": 2,
      "eigen_solver": "randomized",
      "kernel": "sigmoid",
      "n_components": 4
    },
    "4": {
      "alpha": 0.7436704297351775,
      "degree": 3,
      "eigen_solver": "randomized",
      "kernel": "sigmoid",
      "n_components": 3
    }
  },
  "config_origins": {
    "1": "Initial Design: Sobol",
    "2": "Initial Design: Sobol",
    "3": "Acquisition Function Maximizer: Random Search (sorted)",
    "4": "Acquisition Function Maximizer: Random Search (sorted)"
  }
}